Retrieving notices: ...working... Retrying (Retry(total=2, connect=None, read=None, redirect=None, status=None)) after connection broken by 'NameResolutionError("<urllib3.connection.HTTPSConnection object at 0x1465e5fbf260>: Failed to resolve 'repo.anaconda.com' ([Errno -2] Name or service not known)")': /pkgs/r/notices.json

Retrying (Retry(total=2, connect=None, read=None, redirect=None, status=None)) after connection broken by 'NameResolutionError("<urllib3.connection.HTTPSConnection object at 0x1465e5fbf530>: Failed to resolve 'conda.anaconda.org' ([Errno -2] Name or service not known)")': /conda-forge/notices.json

Retrying (Retry(total=2, connect=None, read=None, redirect=None, status=None)) after connection broken by 'NameResolutionError("<urllib3.connection.HTTPSConnection object at 0x1465e9f54860>: Failed to resolve 'repo.anaconda.com' ([Errno -2] Name or service not known)")': /pkgs/main/notices.json

Retrying (Retry(total=1, connect=None, read=None, redirect=None, status=None)) after connection broken by 'NameResolutionError("<urllib3.connection.HTTPSConnection object at 0x1465e5fbf6e0>: Failed to resolve 'repo.anaconda.com' ([Errno -2] Name or service not known)")': /pkgs/r/notices.json

Retrying (Retry(total=1, connect=None, read=None, redirect=None, status=None)) after connection broken by 'NameResolutionError("<urllib3.connection.HTTPSConnection object at 0x1465e5fbfa40>: Failed to resolve 'conda.anaconda.org' ([Errno -2] Name or service not known)")': /conda-forge/notices.json

Retrying (Retry(total=1, connect=None, read=None, redirect=None, status=None)) after connection broken by 'NameResolutionError("<urllib3.connection.HTTPSConnection object at 0x1465e5fbfc50>: Failed to resolve 'repo.anaconda.com' ([Errno -2] Name or service not known)")': /pkgs/main/notices.json

Retrying (Retry(total=0, connect=None, read=None, redirect=None, status=None)) after connection broken by 'NameResolutionError("<urllib3.connection.HTTPSConnection object at 0x1465e5fbfd40>: Failed to resolve 'repo.anaconda.com' ([Errno -2] Name or service not known)")': /pkgs/r/notices.json

Retrying (Retry(total=0, connect=None, read=None, redirect=None, status=None)) after connection broken by 'NameResolutionError("<urllib3.connection.HTTPSConnection object at 0x1465e5fbfe60>: Failed to resolve 'conda.anaconda.org' ([Errno -2] Name or service not known)")': /conda-forge/notices.json

Retrying (Retry(total=0, connect=None, read=None, redirect=None, status=None)) after connection broken by 'NameResolutionError("<urllib3.connection.HTTPSConnection object at 0x1465e5fbff80>: Failed to resolve 'repo.anaconda.com' ([Errno -2] Name or service not known)")': /pkgs/main/notices.json

ERROR conda.notices.fetch:get_channel_notice_response(73): Request error <HTTPSConnectionPool(host='repo.anaconda.com', port=443): Max retries exceeded with url: /pkgs/r/notices.json (Caused by NameResolutionError("<urllib3.connection.HTTPSConnection object at 0x1465e57f42c0>: Failed to resolve 'repo.anaconda.com' ([Errno -2] Name or service not known)"))> for channel: defaults url: https://repo.anaconda.com/pkgs/r/notices.json
ERROR conda.notices.fetch:get_channel_notice_response(73): Request error <HTTPSConnectionPool(host='conda.anaconda.org', port=443): Max retries exceeded with url: /conda-forge/notices.json (Caused by NameResolutionError("<urllib3.connection.HTTPSConnection object at 0x1465e57f43e0>: Failed to resolve 'conda.anaconda.org' ([Errno -2] Name or service not known)"))> for channel: conda-forge url: https://conda.anaconda.org/conda-forge/notices.json
ERROR conda.notices.fetch:get_channel_notice_response(73): Request error <HTTPSConnectionPool(host='repo.anaconda.com', port=443): Max retries exceeded with url: /pkgs/main/notices.json (Caused by NameResolutionError("<urllib3.connection.HTTPSConnection object at 0x1465e57f4500>: Failed to resolve 'repo.anaconda.com' ([Errno -2] Name or service not known)"))> for channel: defaults url: https://repo.anaconda.com/pkgs/main/notices.json
done
Channels:
 - conda-forge
 - defaults
Platform: linux-64
Collecting package metadata (repodata.json): ...working... Retrying (Retry(total=2, connect=None, read=None, redirect=None, status=None)) after connection broken by 'NameResolutionError("<urllib3.connection.HTTPSConnection object at 0x1465e58b2420>: Failed to resolve 'conda.anaconda.org' ([Errno -2] Name or service not known)")': /conda-forge/noarch/repodata.json.zst

Retrying (Retry(total=2, connect=None, read=None, redirect=None, status=None)) after connection broken by 'NameResolutionError("<urllib3.connection.HTTPSConnection object at 0x1465e58b3230>: Failed to resolve 'conda.anaconda.org' ([Errno -2] Name or service not known)")': /conda-forge/linux-64/repodata.json.zst

Retrying (Retry(total=2, connect=None, read=None, redirect=None, status=None)) after connection broken by 'NameResolutionError("<urllib3.connection.HTTPSConnection object at 0x1465e40c4bf0>: Failed to resolve 'repo.anaconda.com' ([Errno -2] Name or service not known)")': /pkgs/main/linux-64/repodata.json.zst

Retrying (Retry(total=2, connect=None, read=None, redirect=None, status=None)) after connection broken by 'NameResolutionError("<urllib3.connection.HTTPSConnection object at 0x1465e40c44a0>: Failed to resolve 'repo.anaconda.com' ([Errno -2] Name or service not known)")': /pkgs/r/linux-64/repodata.json.zst

Retrying (Retry(total=2, connect=None, read=None, redirect=None, status=None)) after connection broken by 'NameResolutionError("<urllib3.connection.HTTPSConnection object at 0x1465e40c5370>: Failed to resolve 'repo.anaconda.com' ([Errno -2] Name or service not known)")': /pkgs/main/noarch/repodata.json.zst

Retrying (Retry(total=2, connect=None, read=None, redirect=None, status=None)) after connection broken by 'NameResolutionError("<urllib3.connection.HTTPSConnection object at 0x1465e40c5b20>: Failed to resolve 'repo.anaconda.com' ([Errno -2] Name or service not known)")': /pkgs/r/noarch/repodata.json.zst

Retrying (Retry(total=1, connect=None, read=None, redirect=None, status=None)) after connection broken by 'NameResolutionError("<urllib3.connection.HTTPSConnection object at 0x1465e58b33e0>: Failed to resolve 'conda.anaconda.org' ([Errno -2] Name or service not known)")': /conda-forge/noarch/repodata.json.zst

Retrying (Retry(total=1, connect=None, read=None, redirect=None, status=None)) after connection broken by 'NameResolutionError("<urllib3.connection.HTTPSConnection object at 0x1465e58b3620>: Failed to resolve 'conda.anaconda.org' ([Errno -2] Name or service not known)")': /conda-forge/linux-64/repodata.json.zst

Retrying (Retry(total=1, connect=None, read=None, redirect=None, status=None)) after connection broken by 'NameResolutionError("<urllib3.connection.HTTPSConnection object at 0x1465e40c5cd0>: Failed to resolve 'repo.anaconda.com' ([Errno -2] Name or service not known)")': /pkgs/main/linux-64/repodata.json.zst

Retrying (Retry(total=1, connect=None, read=None, redirect=None, status=None)) after connection broken by 'NameResolutionError("<urllib3.connection.HTTPSConnection object at 0x1465e40c5e80>: Failed to resolve 'repo.anaconda.com' ([Errno -2] Name or service not known)")': /pkgs/r/linux-64/repodata.json.zst

Retrying (Retry(total=1, connect=None, read=None, redirect=None, status=None)) after connection broken by 'NameResolutionError("<urllib3.connection.HTTPSConnection object at 0x1465e40c6060>: Failed to resolve 'repo.anaconda.com' ([Errno -2] Name or service not known)")': /pkgs/main/noarch/repodata.json.zst

Retrying (Retry(total=1, connect=None, read=None, redirect=None, status=None)) after connection broken by 'NameResolutionError("<urllib3.connection.HTTPSConnection object at 0x1465e40c62d0>: Failed to resolve 'repo.anaconda.com' ([Errno -2] Name or service not known)")': /pkgs/r/noarch/repodata.json.zst

Retrying (Retry(total=0, connect=None, read=None, redirect=None, status=None)) after connection broken by 'NameResolutionError("<urllib3.connection.HTTPSConnection object at 0x1465e5ff50a0>: Failed to resolve 'conda.anaconda.org' ([Errno -2] Name or service not known)")': /conda-forge/noarch/repodata.json.zst

Retrying (Retry(total=0, connect=None, read=None, redirect=None, status=None)) after connection broken by 'NameResolutionError("<urllib3.connection.HTTPSConnection object at 0x1465e5fbf170>: Failed to resolve 'conda.anaconda.org' ([Errno -2] Name or service not known)")': /conda-forge/linux-64/repodata.json.zst

Retrying (Retry(total=0, connect=None, read=None, redirect=None, status=None)) after connection broken by 'NameResolutionError("<urllib3.connection.HTTPSConnection object at 0x1465e5fbc500>: Failed to resolve 'repo.anaconda.com' ([Errno -2] Name or service not known)")': /pkgs/main/linux-64/repodata.json.zst

Retrying (Retry(total=0, connect=None, read=None, redirect=None, status=None)) after connection broken by 'NameResolutionError("<urllib3.connection.HTTPSConnection object at 0x1465e5fbe600>: Failed to resolve 'repo.anaconda.com' ([Errno -2] Name or service not known)")': /pkgs/r/linux-64/repodata.json.zst

Retrying (Retry(total=0, connect=None, read=None, redirect=None, status=None)) after connection broken by 'NameResolutionError("<urllib3.connection.HTTPSConnection object at 0x1465e5fbe690>: Failed to resolve 'repo.anaconda.com' ([Errno -2] Name or service not known)")': /pkgs/main/noarch/repodata.json.zst

Retrying (Retry(total=0, connect=None, read=None, redirect=None, status=None)) after connection broken by 'NameResolutionError("<urllib3.connection.HTTPSConnection object at 0x1465e5fbc4a0>: Failed to resolve 'repo.anaconda.com' ([Errno -2] Name or service not known)")': /pkgs/r/noarch/repodata.json.zst

failed

CondaHTTPError: HTTP 000 CONNECTION FAILED for url <https://conda.anaconda.org/conda-forge/linux-64/repodata.json>
Elapsed: -

An HTTP error occurred when trying to retrieve this URL.
HTTP errors are often intermittent, and a simple retry will get you on your way.
'https//conda.anaconda.org/conda-forge/linux-64'



EnvironmentNameNotFound: Could not find conda environment: sentiment
You can list all discoverable environments with `conda info --envs`.


Traceback (most recent call last):
  File "/home/kr5379/IW-Programming/sent_anal.py", line 4, in <module>
    import torch
ModuleNotFoundError: No module named 'torch'
