cuda
Traceback (most recent call last):
  File "/home/kr5379/.conda/envs/sentiment/lib/python3.13/site-packages/transformers/utils/hub.py", line 424, in cached_files
    hf_hub_download(
    ~~~~~~~~~~~~~~~^
        path_or_repo_id,
        ^^^^^^^^^^^^^^^^
    ...<10 lines>...
        local_files_only=local_files_only,
        ^^^^^^^^^^^^^^^^^^^^^^^^^^^^^^^^^^
    )
    ^
  File "/home/kr5379/.conda/envs/sentiment/lib/python3.13/site-packages/huggingface_hub/utils/_validators.py", line 106, in _inner_fn
    validate_repo_id(arg_value)
    ~~~~~~~~~~~~~~~~^^^^^^^^^^^
  File "/home/kr5379/.conda/envs/sentiment/lib/python3.13/site-packages/huggingface_hub/utils/_validators.py", line 154, in validate_repo_id
    raise HFValidationError(
    ...<2 lines>...
    )
huggingface_hub.errors.HFValidationError: Repo id must be in the form 'repo_name' or 'namespace/repo_name': '/home/kr5379/IW-Programming/go_emotions_model'. Use `repo_type` argument if needed.

During handling of the above exception, another exception occurred:

Traceback (most recent call last):
  File "/home/kr5379/IW-Programming-1/sent_anal_gen.py", line 17, in <module>
    model = AutoModelForSequenceClassification.from_pretrained(model_path)
  File "/home/kr5379/.conda/envs/sentiment/lib/python3.13/site-packages/transformers/models/auto/auto_factory.py", line 492, in from_pretrained
    resolved_config_file = cached_file(
        pretrained_model_name_or_path,
    ...<4 lines>...
        **hub_kwargs,
    )
  File "/home/kr5379/.conda/envs/sentiment/lib/python3.13/site-packages/transformers/utils/hub.py", line 266, in cached_file
    file = cached_files(path_or_repo_id=path_or_repo_id, filenames=[filename], **kwargs)
  File "/home/kr5379/.conda/envs/sentiment/lib/python3.13/site-packages/transformers/utils/hub.py", line 471, in cached_files
    _get_cache_file_to_return(path_or_repo_id, filename, cache_dir, revision) for filename in full_filenames
    ~~~~~~~~~~~~~~~~~~~~~~~~~^^^^^^^^^^^^^^^^^^^^^^^^^^^^^^^^^^^^^^^^^^^^^^^^
  File "/home/kr5379/.conda/envs/sentiment/lib/python3.13/site-packages/transformers/utils/hub.py", line 134, in _get_cache_file_to_return
    resolved_file = try_to_load_from_cache(path_or_repo_id, full_filename, cache_dir=cache_dir, revision=revision)
  File "/home/kr5379/.conda/envs/sentiment/lib/python3.13/site-packages/huggingface_hub/utils/_validators.py", line 106, in _inner_fn
    validate_repo_id(arg_value)
    ~~~~~~~~~~~~~~~~^^^^^^^^^^^
  File "/home/kr5379/.conda/envs/sentiment/lib/python3.13/site-packages/huggingface_hub/utils/_validators.py", line 154, in validate_repo_id
    raise HFValidationError(
    ...<2 lines>...
    )
huggingface_hub.errors.HFValidationError: Repo id must be in the form 'repo_name' or 'namespace/repo_name': '/home/kr5379/IW-Programming/go_emotions_model'. Use `repo_type` argument if needed.
cuda
Traceback (most recent call last):
  File "/home/kr5379/.conda/envs/sentiment/lib/python3.13/site-packages/transformers/utils/hub.py", line 424, in cached_files
    hf_hub_download(
    ~~~~~~~~~~~~~~~^
        path_or_repo_id,
        ^^^^^^^^^^^^^^^^
    ...<10 lines>...
        local_files_only=local_files_only,
        ^^^^^^^^^^^^^^^^^^^^^^^^^^^^^^^^^^
    )
    ^
  File "/home/kr5379/.conda/envs/sentiment/lib/python3.13/site-packages/huggingface_hub/utils/_validators.py", line 106, in _inner_fn
    validate_repo_id(arg_value)
    ~~~~~~~~~~~~~~~~^^^^^^^^^^^
  File "/home/kr5379/.conda/envs/sentiment/lib/python3.13/site-packages/huggingface_hub/utils/_validators.py", line 154, in validate_repo_id
    raise HFValidationError(
    ...<2 lines>...
    )
huggingface_hub.errors.HFValidationError: Repo id must be in the form 'repo_name' or 'namespace/repo_name': '/home/kr5379/IW-Programming/go_emotions_model'. Use `repo_type` argument if needed.

During handling of the above exception, another exception occurred:

Traceback (most recent call last):
  File "/home/kr5379/IW-Programming-1/sent_anal_gen.py", line 17, in <module>
    model = AutoModelForSequenceClassification.from_pretrained(model_path)
  File "/home/kr5379/.conda/envs/sentiment/lib/python3.13/site-packages/transformers/models/auto/auto_factory.py", line 492, in from_pretrained
    resolved_config_file = cached_file(
        pretrained_model_name_or_path,
    ...<4 lines>...
        **hub_kwargs,
    )
  File "/home/kr5379/.conda/envs/sentiment/lib/python3.13/site-packages/transformers/utils/hub.py", line 266, in cached_file
    file = cached_files(path_or_repo_id=path_or_repo_id, filenames=[filename], **kwargs)
  File "/home/kr5379/.conda/envs/sentiment/lib/python3.13/site-packages/transformers/utils/hub.py", line 471, in cached_files
    _get_cache_file_to_return(path_or_repo_id, filename, cache_dir, revision) for filename in full_filenames
    ~~~~~~~~~~~~~~~~~~~~~~~~~^^^^^^^^^^^^^^^^^^^^^^^^^^^^^^^^^^^^^^^^^^^^^^^^
  File "/home/kr5379/.conda/envs/sentiment/lib/python3.13/site-packages/transformers/utils/hub.py", line 134, in _get_cache_file_to_return
    resolved_file = try_to_load_from_cache(path_or_repo_id, full_filename, cache_dir=cache_dir, revision=revision)
  File "/home/kr5379/.conda/envs/sentiment/lib/python3.13/site-packages/huggingface_hub/utils/_validators.py", line 106, in _inner_fn
    validate_repo_id(arg_value)
    ~~~~~~~~~~~~~~~~^^^^^^^^^^^
  File "/home/kr5379/.conda/envs/sentiment/lib/python3.13/site-packages/huggingface_hub/utils/_validators.py", line 154, in validate_repo_id
    raise HFValidationError(
    ...<2 lines>...
    )
huggingface_hub.errors.HFValidationError: Repo id must be in the form 'repo_name' or 'namespace/repo_name': '/home/kr5379/IW-Programming/go_emotions_model'. Use `repo_type` argument if needed.
cuda
Traceback (most recent call last):
  File "/home/kr5379/.conda/envs/sentiment/lib/python3.13/site-packages/transformers/utils/hub.py", line 424, in cached_files
    hf_hub_download(
    ~~~~~~~~~~~~~~~^
        path_or_repo_id,
        ^^^^^^^^^^^^^^^^
    ...<10 lines>...
        local_files_only=local_files_only,
        ^^^^^^^^^^^^^^^^^^^^^^^^^^^^^^^^^^
    )
    ^
  File "/home/kr5379/.conda/envs/sentiment/lib/python3.13/site-packages/huggingface_hub/utils/_validators.py", line 106, in _inner_fn
    validate_repo_id(arg_value)
    ~~~~~~~~~~~~~~~~^^^^^^^^^^^
  File "/home/kr5379/.conda/envs/sentiment/lib/python3.13/site-packages/huggingface_hub/utils/_validators.py", line 154, in validate_repo_id
    raise HFValidationError(
    ...<2 lines>...
    )
huggingface_hub.errors.HFValidationError: Repo id must be in the form 'repo_name' or 'namespace/repo_name': '/home/kr5379/IW-Programming/go_emotions_model'. Use `repo_type` argument if needed.

During handling of the above exception, another exception occurred:

Traceback (most recent call last):
  File "/home/kr5379/IW-Programming-1/sent_anal_gen.py", line 17, in <module>
    model = AutoModelForSequenceClassification.from_pretrained(model_path)
  File "/home/kr5379/.conda/envs/sentiment/lib/python3.13/site-packages/transformers/models/auto/auto_factory.py", line 492, in from_pretrained
    resolved_config_file = cached_file(
        pretrained_model_name_or_path,
    ...<4 lines>...
        **hub_kwargs,
    )
  File "/home/kr5379/.conda/envs/sentiment/lib/python3.13/site-packages/transformers/utils/hub.py", line 266, in cached_file
    file = cached_files(path_or_repo_id=path_or_repo_id, filenames=[filename], **kwargs)
  File "/home/kr5379/.conda/envs/sentiment/lib/python3.13/site-packages/transformers/utils/hub.py", line 471, in cached_files
    _get_cache_file_to_return(path_or_repo_id, filename, cache_dir, revision) for filename in full_filenames
    ~~~~~~~~~~~~~~~~~~~~~~~~~^^^^^^^^^^^^^^^^^^^^^^^^^^^^^^^^^^^^^^^^^^^^^^^^
  File "/home/kr5379/.conda/envs/sentiment/lib/python3.13/site-packages/transformers/utils/hub.py", line 134, in _get_cache_file_to_return
    resolved_file = try_to_load_from_cache(path_or_repo_id, full_filename, cache_dir=cache_dir, revision=revision)
  File "/home/kr5379/.conda/envs/sentiment/lib/python3.13/site-packages/huggingface_hub/utils/_validators.py", line 106, in _inner_fn
    validate_repo_id(arg_value)
    ~~~~~~~~~~~~~~~~^^^^^^^^^^^
  File "/home/kr5379/.conda/envs/sentiment/lib/python3.13/site-packages/huggingface_hub/utils/_validators.py", line 154, in validate_repo_id
    raise HFValidationError(
    ...<2 lines>...
    )
huggingface_hub.errors.HFValidationError: Repo id must be in the form 'repo_name' or 'namespace/repo_name': '/home/kr5379/IW-Programming/go_emotions_model'. Use `repo_type` argument if needed.
